Workbook
Name Title1: WeeklyMealPlanner[[#Headers],[Weekday]]

Sheet Weekly Meal Planner
B1: Fri-EL Ethiopia Farming & Processing PLC
B2: Main Canteen Meal Planner
C3: Number of Employees served | D3: 153 | E3: Period of the service - August 2025 | G3: Omorate Main Canteen
B4: Weekday | C4: Breakfast | D4: Snack | E4: Lunch | F4: Snack2 | G4: Dinner | H4: Snack3 | I4: Remark
B5: Sunday | C5: Rice with Bread & Tea | E5: Fish stew with Enjera | G5: Macaroni Soup with Bread | H5: Banana
B6: Monday | C6: Macorroni with bread & Tea | D6: Papaya Jiuce | E6: Meat Stew with Enjera | G6: Potato Stew + Moringa with Enjera
B7: Tuesday | C7: Injera Firfir with meat, Bread & Tea | E7: Split peas stew + Cabage with Enjera | F7: Banana | G7: Shiro + Alicha Kik with Enjera
B8: Wednesday | C8: Rice with Haricotbean, Bread & Tea | E8: Split Lentil + Moringa with Enjera | G8: Pasta with tomatoe souce
B9: Thursday | C9: Kinche, Bread & Tea | E9: Meat & potato stew with Enjera | G9: Whole Lentil + Moringa with Enjera
B10: Friday | C10: Pasta with vegetables and tea | D10: Papaya Jiuce | E10: Shiro + Gomen with Enjera | F10: Papaya Jiuce | G10: Rice with potato
B11: Saturday | C11: Tomatoe sauce with bread and tea | E11: Whole lentil + Carrot/beetroot with Enjera | G11: Macoroni with bread
B14: Sunday | C14: Items | D14: U.o.M | E14: Total Quantity | F14: Unit Price | G14: Total Cost
C15: Rice | D15: Kg. | E15: =(D3*Percapita!D7)/1000 -> 30.6 | F15: 140 | G15: =E15*F15 -> 4284
C16: Wheat Flour | D16: Kg. | E16: =((D3*Percapita!D14)/1000)*2 -> 30.6 | F16: 120 | G16: =E16*F16 -> 3672
C17: Teff Flour | D17: Kg. | E17: =(D3*Percapita!D13)/1000 -> 25.5 | F17: 120 | G17: =E17*F17 -> 3060
C18: Fish meat | D18: Kg. | E18: =(D3*Percapita!D3)/1000 -> 30.6 | F18: 400 | G18: =E18*F18 -> 12240
C19: Macaroni | D19: Kg. | E19: =(D3*Percapita!D6)/1000 -> 51 | F19: 140 | G19: =E19*F19 -> 7140
C20: Oil | D20: Lt. | E20: =((D3*Percapita!D11)/1000)*3 -> 11.475 | F20: 340 | G20: =E20*F20 -> 3901.5
C21: Onion | D21: Kg. | E21: =((D3*Percapita!D8)/1000)*3 -> 11.475 | F21: =Percapita!F8 -> 100 | G21: =E21*F21 -> 1147.5
C22: Salt | D22: Kg. | E22: =((D3*Percapita!D20)/1000)*3 -> 0.2295 | F22: =Percapita!F20 -> 50 | G22: =E22*F22 -> 11.475
C23: Sugar | D23: Kg. | E23: =(D3*Percapita!D15)/1000 -> 2.295 | F23: =Percapita!F15 -> 160 | G23: =E23*F23 -> 367.2
C24: Tea | D24: Pkt | E24: =(D3*Percapita!D26) -> 1.224 | F24: =Percapita!F26 -> 35 | G24: =E24*F24 -> 42.84
B27: Monday | C27: Macaroni | D27: Kg. | E27: =(D3*Percapita!D6)/1000 -> 51 | F27: =+F19 -> 140 | G27: =E27*F27 -> 7140
C28: Wheat Flour | D28: Kg. | E28: =(D3*Percapita!D14)/1000 -> 15.3 | F28: =+Percapita!F14 -> 120 | G28: =E28*F28 -> 1836
C29: Teff Flour | D29: Kg. | E29: =((D3*Percapita!D13)/1000)*2 -> 51 | F29: =+Percapita!F13 -> 120 | G29: =E29*F29 -> 6120
C30: Meat | D30: Kg. | E30: =(D3*Percapita!D4)/1000 -> 30.6 | F30: =+Percapita!F4 -> 1200 | G30: =E30*F30 -> 36720
C31: Oil | D31: Lt. | E31: =((D3*Percapita!D11/1000)*3) -> 11.475 | F31: =+Percapita!F11 -> 340 | G31: =E31*F31 -> 3901.5
C32: Onion | D32: Kg. | E32: =((D3*Percapita!D8)/1000)*3 -> 11.475 | F32: =+Percapita!F8 -> 100 | G32: =E32*F32 -> 1147.5
C33: Salt | D33: Kg. | E33: =((Percapita!D20*'Weekly Meal Planner'!D3)/1000)*3 -> 0.2295 | F33: =+Percapita!F20 -> 50 | G33: =E33*F33 -> 11.475
C34: Sugar | D34: Kg. | E34: =(D3*Percapita!D15)/1000 -> 2.295 | F34: =+Percapita!F15 -> 160 | G34: =E34*F34 -> 367.2
C35: Tea | D35: Pkt | E35: =(D3*Percapita!D26) -> 1.224 | F35: =+Percapita!F26 -> 35 | G35: =E35*F35 -> 42.84
C36: Pepper | D36: Kg. | E36: =((D3*Percapita!D10)/1000)*2 -> 3.825 | F36: =+Percapita!F10 -> 680 | G36: =E36*F36 -> 2601
C37: Potato | D37: Kg. | E37: =(D3*Percapita!D23)/1000 -> 15.3 | F37: =+Percapita!F23 -> 50 | G37: =E37*F37 -> 765
C38: Moringa | D38: Esir | E38: =(Percapita!H24*0) -> 0 | G38: =E38*F38 -> 0
C39: Garlic | D39: Kg. | E39: =((D3*Percapita!D12)/1000)*2 -> 1.36 | F39: =+Percapita!F12 -> 400 | G39: =E39*F39 -> 544
B41: Tuesday | C41: Wheat Flour | D41: Kg. | E41: =(D3*Percapita!D14)/1000 -> 15.3 | F41: =+Percapita!F14 -> 120 | G41: =E41*F41 -> 1836
C42: Teff Flour | D42: Kg. | E42: =((D3*Percapita!D13)/1000)*3 -> 76.5 | F42: =+Percapita!F13 -> 120 | G42: =E42*F42 -> 9180
C43: Meat | D43: Kg. | E43: =(D3*Percapita!D4)/1000/2 -> 15.3 | F43: =+Percapita!F4 -> 1200 | G43: =E43*F43 -> 18360
C44: Oil | D44: Lt. | E44: =((D3*Percapita!D11)/1000)*3 -> 11.475 | F44: =+Percapita!F11 -> 340 | G44: =E44*F44 -> 3901.5
C45: Onion | D45: Kg. | E45: =((D3*Percapita!D8)/1000)*5 -> 19.125 | F45: =+Percapita!F8 -> 100 | G45: =E45*F45 -> 1912.5
...

Sheet Percapita
A1: የነፍስ ወከፍ ፍላጎት ስሌት
A2: ተ.ቁ | B2: የዕቃዉ ዓይነት | C2: መለኪያ | D2: ለአንድ ሰው | E2: መለኪያ2 | F2: ዋጋ
A3: 1 | B3: አሳ | C3: ግራም | D3: 200 | E3: ኪሎ | F3: 400
A4: 2 | B4: ስጋ | C4: ግራም | D4: 200 | E4: ኪሎ | F4: 1200
A5: 3 | B5: ፓሰታ | C5: ግራም | D5: =500/4 -> 125 | E5: 1/2ኪ | F5: 90
A6: 4 | B6: መኮረኒ | C6: ግራም | D6: =1000/3 -> 333.33333 | E6: ኪሎ | F6: 140
A7: 5 | B7: ሩዝ | C7: ግራም | D7: =1000/5 -> 200 | E7: " | F7: 140
A8: 6 | B8: ቀይ ሽንኩርት | C8: ግራም | D8: 25 | E8: " | F8: 100 | H8: =200/1000 -> 0.2
A9: 7 | B9: ቲማቲም | C9: ግራም | D9: 35 | E9: " | F9: 65
A10: 8 | B10: በርበሬ | C10: ግራም | D10: =250/20 -> 12.5 | E10: " | F10: =170*4 -> 680
A11: 9 | B11: ዘይት | C11: ሚሊ | D11: =500/20 -> 25 | E11: ሊትር | F11: =1700/5 -> 340
A12: 10 | B12: ነጭ ሽንኩርት | C12: ግራም | D12: =8000/30/3/20 -> 4.4444444 | E12: ኪሎ | F12: 400
A13: 11 | B13: ጤፍ | C13: ግራም | D13: =1000/6 -> 166.66667 | E13: ኪሎ | F13: =6000/50 -> 120
A14: 12 | B14: ፉርኖ ዱቄት | C14: ግራም | D14: 100 | E14: ኪሎ | F14: 120
A15: 13 | B15: ስኳር | C15: ግራም | D15: 15 | E15: ኪሎ | F15: 160
A16: 14 | B16: አተር ክክ | C16: ግራም | D16: 25 | E16: ኪሎ | F16: 200
A17: 15 | B17: ሸሮ | C17: ግራም | D17: 100 | E17: ኪሎ | F17: 220
A18: 16 | B18: ድፍን ምስር | C18: ግራም | D18: =250/20 -> 12.5 | E18: ኪሎ | F18: 270
A19: 17 | B19: እርድ | C19: ግራም | D19: 0.5 | E19: ኪሎ | F19: =4*250 -> 1000
A20: 18 | B20: ጨው | C20: ግራም | D20: 0.5 | E20: ኪሎ | F20: 50
A21: 19 | B21: አበሻ ጎመን | C21: እስር | D21: =2/150 -> 0.013333333 | E21: እስር | F21: 400
A22: 20 | B22: ጥቅል ጎመን | C22: ግራም | D22: =1000/10 -> 100 | E22: ኪሎ
A23: 21 | B23: ድንች | C23: ግራም | D23: =100 -> 100 | E23: ኪሎ | F23: 50
A24: 22 | B24: ቀይ ስር | C24: ግራም | D24: 50 | E24: ኪሎ | F24: 50
A25: 23 | B25: ካሮት | C25: ግራም | D25: 25 | E25: ኪሎ | F25: 60
A26: 24 | B26: ሻይ ቅጠል | C26: ፓኬት | D26: =1.2/150 -> 0.008 | E26: ፓኬት | F26: 35
A27: 25 | B27: ሻይ ቅመም | C27: እሽግ | D27: =3/30/150 -> 0.00066666667 | E27: እሽግ
A28: 26 | B28: ቦለቄ | C28: ግራም | D28: 75 | E28: ኪሎ | F28: 180
A29: 27 | B29: ቅንጬ | C29: ግራም | D29: 150 | E29: ኪሎ | F29: 325
A30: 28 | B30: ምስር | C30: ግራም | D30: 20 | E30: ኪሎ | F30: 300
